<?xml version="1.0"?>

<!-- Limits in urdf are ignored, they need to be added in the IK module -->
<robot name="custom_kemrox_robot">

  <link name="base_link">
    <visual>
      <origin xyz="0 0 0" rpy="0 0 0" />
      <geometry>
        <mesh filename="package://dnb_kemrox_custom_robot/meshes/base_link.dae"/>
      </geometry>
      <material name="material"/>
    </visual>
  </link>

  <link name="link_1">
    <visual>
      <origin xyz="0 0 0" rpy="0 0 0" />
      <geometry>
        <mesh filename="package://dnb_kemrox_custom_robot/meshes/link_1.dae"/>
      </geometry>
      <material name="material"/>
    </visual>
  </link>

  <link name="link_2" >
    <visual>
      <origin xyz="0 0 0" rpy="0 0 0" />
      <geometry>
        <mesh filename="package://dnb_kemrox_custom_robot/meshes/link_2.dae"/>
      </geometry>
      <material name="material">
      </material>
    </visual>
  </link>

  <link name="link_3" >
    <visual>
      <origin xyz="0 0 0" rpy="0 0 0" />
      <geometry>
        <mesh filename="package://dnb_kemrox_custom_robot/meshes/link_3.dae"/>
      </geometry>
      <material name="material">
      </material>
    </visual>
  </link>

  <link name="link_4">
    <visual>
      <origin xyz="0 0 0" rpy="0 0 0" />
      <geometry>
        <mesh filename="package://dnb_kemrox_custom_robot/meshes/link_4.dae"/>
      </geometry>
      <material name="material">
      </material>
    </visual>
  </link>

  <link name="link_5" >
    <visual>
      <origin xyz="0 0 0" rpy="0 0 0" />
      <geometry>
        <mesh filename="package://dnb_kemrox_custom_robot/meshes/link_5.dae"/>
      </geometry>
      <material name="material">
      </material>
    </visual>
  </link>

  <link name="link_6">
    <visual>
      <origin xyz="0 0 0" rpy="0 0 0" />
      <geometry>
        <mesh filename="package://dnb_kemrox_custom_robot/meshes/link_6.dae"/>
      </geometry>
      <material name="material">
      </material>
    </visual>
  </link>

  <link name="ee_link" />

  <joint name="joint_1" type="revolute">
    <origin xyz="0 0 0.176" rpy="0 0 0" />
    <parent link="base_link"/>
    <child link="link_1"/>
    <axis xyz="0 0 -1"/>
    <limit lower="-0.733" upper="3.875" effort="0" velocity="7.85398"/>
  </joint>

  <joint name="joint_2" type="revolute">
    <origin xyz="0.15 -0.09 0.254" rpy="0 0 0" />
    <parent link="link_1"/>
    <child link="link_2"/>
    <axis xyz="0 1 0"/>
    <limit lower="-2.461" upper="2.461" effort="0" velocity="7.85398"/>
  </joint>

  <joint name="joint_3" type="revolute">
    <origin xyz="0 0 0.59" rpy="0 -1.5708 0" />
    <parent link="link_2"/>
    <child link="link_3"/>
    <axis xyz="0 -1 0"/>
    <limit lower="-0.15" upper="0.0" effort="0" velocity="8.97099"/>
  </joint>

  <joint name="joint_4" type="revolute">
    <parent link="link_3"/>
    <child link="link_4"/>
    <origin xyz="0.1 0.09 0.13" rpy="0 0 0" />
    <axis xyz="-1 0 0"/>
    <limit lower="-6.283" upper="6.283" effort="0" velocity="8.97099"/>
  </joint>

  <joint name="joint_5" type="revolute">
    <parent link="link_4"/>
    <child link="link_5"/>
    <origin xyz="0.584 0.0015 0" rpy="0 0 0" />
    <axis xyz="0 1 0"/>
    <limit lower="-6.283" upper="6.283" effort="0" velocity="8.97099"/>
  </joint>

  <joint name="joint_6" type="revolute">
    <parent link="link_5"/>
    <child link="link_6"/>
    <origin xyz="0.1 -0.0015 0" rpy="0 0 0" />
    <axis xyz="-1 0 0"/>
    <limit lower="-6.283" upper="6.283" effort="0" velocity="8.97099"/>
  </joint>

  <joint name="joint_6_ee_link" type="fixed">
    <parent link="link_6"/>
    <child link="ee_link"/>
    <origin xyz="0 0 0" rpy="0 0 0" />
  </joint>

</robot>
